Workbook

Sheet 委托书
E3: 代 理 报 关 委 托 书
G5: 编号：00451437006
C6: =报关单!V11 -> 0
B7: 我单位现 A (A逐票、B长期)委托贵公司代理 AB 等通关事宜。（A、填单申报 B、辅助查验 C、
B8: 垫缴税款 D、办理海关证明联 E、审批手册 F、核销手册 G、申办减免税手续 H、其他 ）详见《委托报关协
B9: 议》。
B10: 我单位保证遵守《海关法》和国家有关法规，保证所提供的情况真实、完整、单货相符，无侵犯他
B11: 人知识产权的行为。否则，愿承担相关法律责任。
B12: 本委托书有效期自签字之日起至 | E12: 2025 年 12 月 31 日止。
G13: 委托方（盖章）：
D15: 法定代表人或其授权签署《代理报关委托书》的人（签字）
H16: 46173
E18: 委 托 报 关 协 议
B20: 为明确委托报关具体事项和各自责任，双方经平等协商签定协议如下：
B21: 委托方 | C21: =报关单!A4 -> 深圳市比苛电池有限公司 | G21: 被委托方 | H21: =报关单!Y11 -> 0
B22: 主要货物名称 | C22: =发票!C9 -> 锂电池 | G22: *报关单编码
B23: HS编码 | C23: =报关单!B20 -> 8507600090 | G23: 收到单证日期 | H23: =TODAY() -> 46161
B24: 货物总价 | C24: =发票!G23 -> 美元 | D24: =发票!H23 -> 24242 | G24: 收到单证情况 | H24: 合同□√ | I24: 发票□√
B25: 进出口日期 | C25: =报关单!L3 -> 46161 | H25: 装箱清单□√ | I25: 提（运）单□
B26: 提单号 | H26: 加工贸易手册□ | I26: 许可证件□
B27: 贸易方式 | C27: =报关单!E8 -> 一般贸易 | H27: 其他
B28: 原产地/货源地 | C28: =报关单!P20 -> 深圳 | G28: 报关收费 | H28: 人民币： 元
B29: 其他要求： | G29: 承诺说明：
B36: 背面所列通用条款是本协议不可分割的一部分，对本协议的签署构成了对背面通用条款的同意。 | G36: 背面所列通用条款是本协议不可分割的一部分，对本协议的签署构成了对背面通用条款的同意。
B39: 委托方业务签章： | G39: 被委托方业务签章：
B44: 经办人签章： | G44: 经办报关员签章：
B45: 联系电话： | E45: =TODAY()-1 -> 46160 | G45: 联系电话： | I45: =TODAY() -> 46161
C48: （白联：海关留存、黄联：被委托方留存、红联：委托方留存） | I48: 中国报关协会监制

Sheet 报关单
A1: 中华人民共和国海关出口货物报关单
A2: 预录入编号： | F2: 申报口岸: | I2: 海关编号: | J2: 4453161089
A3: 境内发货人 | C3: 9144030078527617XT | E3: 出境关别 | F3: ( ) | G3: 出口日期 | K3: 申报日期 | L3: =委托书!I45 -> 46161 | O3: 备案号 | U3: 签约地点： | V3: 深圳
A4: 深圳市比苛电池有限公司 | E4: 皇岗口岸 | U4: 成交方式: | V4: =I12 -> FOB | W4: SHENZHEN | X4: 付款条件： | Y4: 电汇
A5: 境外收货人 | C5: AEO： | E5: 运输方式 | F5: ( ) | G5: 运输工具名称及航次号 | K5: 提运单号 | U5: 卖方公司： | V5: =A4 -> 深圳市比苛电池有限公司
A6: DURNERGY Inc. | U6: 卖方地址： | V6: 深圳市龙华区民塘路328号鸿荣源北路中心B座9层
A7: 生产销售单位 | C7: =C3 -> 9144030078527617XT | E7: 监管方式 | F7: ( ) | G7: 征免性质 | H7: ( ) | K7: 许可证号 | U7: 卖方电话： | V7: 0755-86670672 | X7: 卖方传真： | Y7: 0755-86670609
A8: =A4 -> 深圳市比苛电池有限公司 | E8: 一般贸易 | G8: 一般征税 | U8: 买方公司： | V8: =A6 -> DURNERGY Inc.
A9: 合同协议号 | E9: 贸易国(地区) | F9: ( ) | G9: 运抵国(地区) | H9: ( ) | K9: 指运港 | L9: ( ) | O9: 离境口岸 | P9: ( )跨境的才需要申报 | U9: 买方地址： | V9: Lot C1, Que Vo IP, Van Duong Ward, Bac Ninh city, Bac Ninh Province, Vietnam
A10: PK-260512006 | E10: 美国 | G10: 美国 | K10: =G10 -> 美国 | U10: 买方电话： | V10: +84-2222 3634300 | X10: 买方传真： | Y10: +84-2222 3634308
A11: 包装种类 | C11: ( ) | E11: 件数 | F11: 毛重（千克） | G11: 净重（千克） | I11: 成交方式 | J11: ( ) | K11: 运费 | N11: 保费 | Q11: 杂费 | U11: 报关简称： | X11: 报关全称：
A12: 纸箱 | E12: =箱单!C18 -> 25 | F12: =箱单!F18 -> 210.2 | G12: =箱单!G18 -> 197.7 | I12: FOB | T12: 境外收货人： | W12: 境外收货人通常指签订并执行出口贸易合同中的买方或合同指定的收货人，名称一般填报英文名称，检验检疫要求填报其他外文名称的，在英文名称后填报，以半角括号分隔。
A13: 随附单证及编号 | T13: 境外收货人代码： | W13: 非互认国家（地区）AEO企业等其他情形，编码免于填报。对于AEO互认国家（地区）企业的，编码填报AEO编码，填报样式按照海关总署发布的相关公告要求填报（如新加坡AEO企业填报样式为：SG123456789012，韩国AEO企业填报样式为KR1234567，具体见相关公告要求）。
A14: 境外收货人完整显示： | D14: =A6 -> DURNERGY Inc. | T14: 检验检疫附加编号： | W14: 通过以下网站输入10位HS编号，再根据申报要素细分确定3位检疫附加编号
A15: 标记唛码及备注： | T15: 检疫局网址-编码查询： | W15: https://e-service.shciq.gov.cn/shesp/
A16: 备注： | T16: 查申报要素网址： | W16: http://www.hscode.net/IntegrateQueries/QueryYS/
L17: 报关联系电话： | T17: 合计： | W17: 贸易国：出口是指合同买方所在的国家（地区），需填写准确，以后可能会影响收汇。
A18: 特殊关系确认: | D18: 价格影响确认： | F18: 支付特许权使用费: | I18: 自报自缴: | K18: 出口不填 | L18: 原产国/目的国/货源地未注明的项默认与提供的项相同 | T18: =SUM(T20:T426) -> 0 | U18: =SUM(U20:U426) -> 0 | V18: =SUM(V20:V426) -> 0
A19: 项号 | B19: 商品编号 | D19: 商品名称及规格型号 | G19: 数量及单位 | I19: 单价/总价/币制 | K19: 原产国（地区） | M19: 最终目的国（地区） | P19: 境内货源地 | S19: 征免 | T19: 净重 | U19: 毛重 | V19: 件数
A20: 1 | B20: 8507600090 | D20: 锂电池 | I20: 0.85 | K20: 中国 | M20: =G10 -> 美国 | P20: 深圳 | S20: 照章征税
B21: 102 | D21: 1|2|玩具用|方形|锂离子|PKCELL|LP502030|250mAh|不含汞|3.7V 比能量133.44WH/KG | I21: =G22*I20 -> 24242
G22: 28520 | H22: 个 | I22: 美元
A23: 21
A26: 22
A29: 23
A32: 24
A35: 25
A38: 26
A41: 27
A44: 28
A47: 29
A50: 30
A53: 31
A56: 32
... A110: 50
BY125: 表格制作单位：深圳市长来运报关有限公司QQ1152276688

Sheet 合同
B2: 合 同 SALES CONTRACT
B3: 卖 方： | C3: =报关单!V5 -> 深圳市比苛电池有限公司
B4: Sellers:
B5: 地 址： | C5: 深圳市龙华区民塘路328号鸿荣源北路中心B座9层
B6: Address: | F6: 合同号码
B7: 电 话： | C7: 0755-86670672 | D7: 传 真 | E7: 0755-86670609 | F7: Contract No: | G7: =报关单!A10 -> PK-260512006
B8: TEL: | D8: FAX: | F8: 日 期
B9: 买 方： | C9: =报关单!V8 -> DURNERGY Inc. | F9: Date: | G9: =报关单!L3 -> 46161
B10: Buyers： | F10: 签约地点
B11: 地 址： | F11: Signed at: | G11: =报关单!V3 -> 深圳
B12: Address: | F12: 成交方式： Trade Term: | G12: =报关单!V4 -> FOB | H12: =报关单!W4 -> SHENZHEN
B13: 电 话 | C13: =报关单!V10 -> +84-2222 3634300 | D13: 传 真
B14: TEL: | D14: FAX:
B15: 经买卖双方确认根据下列条款订立本合同
B16: This contract is made out by the Sellers and Buyers as per the following terms and conditions mutuilly confirmed:
B17: (1)货物名称 | D17: (2) 数 量 | E17: (3)单 位 | F17: (4)单价 | G17: (5) 金 额
B18: Name of commodity | D18: Quantity | E18: Unit | F18: Unit Price | G18: Amount
B19: =发票!C9 -> 锂电池 | D19: =发票!D9 -> 28520 | E19: =发票!E9 -> 个 | F19: =发票!F9 -> 0.85 | G19: =发票!G9 -> 美元 | H19: =发票!H9 -> 24242
B20: =发票!C10 -> 0 | D20: =发票!D10 -> 0 | E20: =发票!E10 -> 0 | F20: =发票!F10 -> 0 | G20: =发票!G10 -> 0 | H20: =发票!H10 -> 0
B21: =发票!C11 -> 0 | D21: =发票!D11 -> 0 | E21: =发票!E11 -> 0 | F21: =发票!F11 -> 0 | G21: =发票!G11 -> 0 | H21: =发票!H11 -> 0
B22: =发票!C12 -> 0 | D22: =发票!D12 -> 0 | E22: =发票!E12 -> 0 | F22: =发票!F12 -> 0 | G22: =发票!G12 -> 0 | H22: =发票!H12 -> 0
B23: =发票!C13 -> 0 | D23: =发票!D13 -> 0 | E23: =发票!E13 -> 0 | F23: =发票!F13 -> 0 | G23: =发票!G13 -> 0 | H23: =发票!H13 -> 0
B24: =发票!C14 -> 0 | D24: =发票!D14 -> 0 | E24: =发票!E14 -> 0 | F24: =发票!F14 -> 0 | G24: =发票!G14 -> 0 | H24: =发票!H14 -> 0
B25: =发票!C15 -> 0 | D25: =发票!D15 -> 0 | E25: =发票!E15 -> 0 | F25: =发票!F15 -> 0 | G25: =发票!G15 -> 0 | H25: =发票!H15 -> 0
B26: =发票!C16 -> 0 | D26: =发票!D16 -> 0 | E26: =发票!E16 -> 0 | F26: =发票!F16 -> 0 | G26: =发票!G16 -> 0 | H26: =发票!H16 -> 0
B27: =发票!C17 -> 0 | D27: =发票!D17 -> 0 | E27: =发票!E17 -> 0 | F27: =发票!F17 -> 0 | G27: =发票!G17 -> 0 | H27: =发票!H17 -> 0
B28: =发票!C18 -> 0 | D28: =发票!D18 -> 0 | E28: =发票!E18 -> 0 | F28: =发票!F18 -> 0 | G28: =发票!G18 -> 0 | H28: =发票!H18 -> 0
B29: =发票!C19 -> 0 | D29: =发票!D19 -> 0 | E29: =发票!E19 -> 0 | F29: =发票!F19 -> 0 | G29: =发票!G19 -> 0 | H29: =发票!H19 -> 0
B30: =发票!C20 -> 0 | D30: =发票!D20 -> 0 | E30: =发票!E20 -> 0 | F30: =发票!F20 -> 0 | G30: =发票!G20 -> 0 | H30: =发票!H20 -> 0
B31: =发票!C21 -> 0 | D31: =发票!D21 -> 0 | E31: =发票!E21 -> 0 | F31: =发票!F21 -> 0 | G31: =发票!G21 -> 0 | H31: =发票!H21 -> 0
B32: =发票!C22 -> 0 | D32: =发票!D22 -> 0 | E32: =发票!E22 -> 0 | F32: =发票!F22 -> 0 | G32: =发票!G22 -> 0 | H32: =发票!H21 -> 0
B33: =发票!C22 -> 0 | D33: =发票!D23 -> 0 | E33: =发票!E22 -> 0 | F33: =发票!F22 -> 0 | G33: =发票!G22 -> 0 | H33: =发票!H22 -> 0
B34: =发票!B18 -> 0 | D34: =发票!D18 -> 0 | E34: =发票!E18 -> 0 | F34: =发票!F18 -> 0 | G34: =发票!G18 -> 0 | H34: =发票!H18 -> 0
B37: 数量及总值允许有 2 %的增减。 | F37: 总 值 | G37: =G19 -> 美元 | H37: =SUM(H19:I36) -> 24242
B38: 2 % more or less both in amount and quantity allowed. | F38: Total Amount:
B39: (6)合同总值（大写） | D39: =IF(G37="CNY","总计人民币:",IF(G37="USD","总计美元: "," ")) | E39: =H37 -> 24242
B40: Total Value in Word: FORTY TWO THOUSAND FOUR HUNDRED AND SEVENTY THREE AND CENTS TWENTY EIGHT ONLY.
B41: (7)包装及唛头
B42: Packing and shipping Marks:
B43: (8)装运期
...

Sheet 发票
A2: 發票 INVOICE
F3: 編 號 NO: | G3: =报关单!A10 -> PK-260512006
A4: 商 號 Sold to Massrs: | C4: =报关单!A6 -> DURNERGY Inc. | F4: 日 期 DATE: | G4: =TODAY() -> 46161
F7: 成交方式： | G7: =报关单!V4 -> FOB | H7: =报关单!W4 -> SHENZHEN
A8: 標記號碼 Mark & No | C8: 貨物名稱 Description | D8: 數量 Quantity | F8: 單價 Unit price | G8: 總金額 Amount
C9: =OFFSET(报关单!$D$1,ROW(报关单!D1)*3+16,0) -> 锂电池 | D9: =OFFSET(报关单!$G$1,ROW(报关单!G1)*3+18,0) -> 28520 | E9: =OFFSET(报关单!$H$1,ROW(报关单!H1)*3+18,0) -> 个 | F9: =IFERROR(H9/D9,0) -> 0.85 | G9: =OFFSET(报关单!$I$1,ROW(报关单!I1)*3+18,0) -> 美元 | H9: =OFFSET(报关单!$I$1,ROW(报关单!I1)*3+17,0) -> 24242
C10: =OFFSET(报关单!$D$1,ROW(报关单!D2)*3+16,0) -> 0 | D10: =OFFSET(报关单!$G$1,ROW(报关单!G2)*3+18,0) -> 0 | E10: =OFFSET(报关单!$H$1,ROW(报关单!H2)*3+18,0) -> 0 | F10: =IFERROR(H10/D10,0) -> 0 | G10: =OFFSET(报关单!$I$1,ROW(报关单!I2)*3+18,0) -> 0 | H10: =OFFSET(报关单!$I$1,ROW(报关单!I2)*3+17,0) -> 0
C11: =OFFSET(报关单!$D$1,ROW(报关单!D3)*3+16,0) -> 0 | D11: =OFFSET(报关单!$G$1,ROW(报关单!G3)*3+18,0) -> 0 | E11: =OFFSET(报关单!$H$1,ROW(报关单!H3)*3+18,0) -> 0 | F11: =IFERROR(H11/D11,0) -> 0 | G11: =OFFSET(报关单!$I$1,ROW(报关单!I3)*3+18,0) -> 0 | H11: =OFFSET(报关单!$I$1,ROW(报关单!I3)*3+17,0) -> 0
C12: =OFFSET(报关单!$D$1,ROW(报关单!D4)*3+16,0) -> 0 | D12: =OFFSET(报关单!$G$1,ROW(报关单!G4)*3+18,0) -> 0 | E12: =OFFSET(报关单!$H$1,ROW(报关单!H4)*3+18,0) -> 0 | F12: =IFERROR(H12/D12,0) -> 0 | G12: =OFFSET(报关单!$I$1,ROW(报关单!I4)*3+18,0) -> 0 | H12: =OFFSET(报关单!$I$1,ROW(报关单!I4)*3+17,0) -> 0
C13: =OFFSET(报关单!$D$1,ROW(报关单!D5)*3+16,0) -> 0 | D13: =OFFSET(报关单!$G$1,ROW(报关单!G5)*3+18,0) -> 0 | E13: =OFFSET(报关单!$H$1,ROW(报关单!H5)*3+18,0) -> 0 | F13: =IFERROR(H13/D13,0) -> 0 | G13: =OFFSET(报关单!$I$1,ROW(报关单!I5)*3+18,0) -> 0 | H13: =OFFSET(报关单!$I$1,ROW(报关单!I5)*3+17,0) -> 0
C14: =OFFSET(报关单!$D$1,ROW(报关单!D6)*3+16,0) -> 0 | D14: =OFFSET(报关单!$G$1,ROW(报关单!G6)*3+18,0) -> 0 | E14: =OFFSET(报关单!$H$1,ROW(报关单!H6)*3+18,0) -> 0 | F14: =IFERROR(H14/D14,0) -> 0 | G14: =OFFSET(报关单!$I$1,ROW(报关单!I6)*3+18,0) -> 0 | H14: =OFFSET(报关单!$I$1,ROW(报关单!I6)*3+17,0) -> 0
C15: =OFFSET(报关单!$D$1,ROW(报关单!D7)*3+16,0) -> 0 | D15: =OFFSET(报关单!$G$1,ROW(报关单!G7)*3+18,0) -> 0 | E15: =OFFSET(报关单!$H$1,ROW(报关单!H7)*3+18,0) -> 0 | F15: =IFERROR(H15/D15,0) -> 0 | G15: =OFFSET(报关单!$I$1,ROW(报关单!I7)*3+18,0) -> 0 | H15: =OFFSET(报关单!$I$1,ROW(报关单!I7)*3+17,0) -> 0
C16: =OFFSET(报关单!$D$1,ROW(报关单!D8)*3+16,0) -> 0 | D16: =OFFSET(报关单!$G$1,ROW(报关单!G8)*3+18,0) -> 0 | E16: =OFFSET(报关单!$H$1,ROW(报关单!H9)*3+18,0) -> 0 | F16: =IFERROR(H16/D16,0) -> 0 | G16: =OFFSET(报关单!$I$1,ROW(报关单!I9)*3+18,0) -> 0 | H16: =OFFSET(报关单!$I$1,ROW(报关单!I8)*3+17,0) -> 0
C17: =OFFSET(报关单!$D$1,ROW(报关单!D9)*3+16,0) -> 0 | D17: =OFFSET(报关单!$G$1,ROW(报关单!G9)*3+18,0) -> 0 | E17: =OFFSET(报关单!$H$1,ROW(报关单!H10)*3+18,0) -> 0 | F17: =IFERROR(H17/D17,0) -> 0 | G17: =OFFSET(报关单!$I$1,ROW(报关单!I10)*3+18,0) -> 0 | H17: =OFFSET(报关单!$I$1,ROW(报关单!I9)*3+17,0) -> 0
C18: =OFFSET(报关单!$D$1,ROW(报关单!D10)*3+16,0) -> 0 | D18: =OFFSET(报关单!$G$1,ROW(报关单!G10)*3+18,0) -> 0 | E18: =OFFSET(报关单!$H$1,ROW(报关单!H11)*3+18,0) -> 0 | F18: =IFERROR(H18/D18,0) -> 0 | G18: =OFFSET(报关单!$I$1,ROW(报关单!I11)*3+18,0) -> 0 | H18: =OFFSET(报关单!$I$1,ROW(报关单!I10)*3+17,0) -> 0
C19: =OFFSET(报关单!$D$1,ROW(报关单!D11)*3+16,0) -> 0 | D19: =OFFSET(报关单!$G$1,ROW(报关单!G11)*3+18,0) -> 0 | E19: =OFFSET(报关单!$H$1,ROW(报关单!H12)*3+18,0) -> 0 | F19: =IFERROR(H19/D19,0) -> 0 | G19: =OFFSET(报关单!$I$1,ROW(报关单!I12)*3+18,0) -> 0 | H19: =OFFSET(报关单!$I$1,ROW(报关单!I11)*3+17,0) -> 0
C20: =OFFSET(报关单!$D$1,ROW(报关单!D12)*3+16,0) -> 0 | D20: =OFFSET(报关单!$G$1,ROW(报关单!G12)*3+18,0) -> 0 | E20: =OFFSET(报关单!$H$1,ROW(报关单!H13)*3+18,0) -> 0 | F20: =IFERROR(H20/D20,0) -> 0 | G20: =OFFSET(报关单!$I$1,ROW(报关单!I13)*3+18,0) -> 0 | H20: =OFFSET(报关单!$I$1,ROW(报关单!I12)*3+17,0) -> 0
C21: =OFFSET(报关单!$D$1,ROW(报关单!D13)*3+16,0) -> 0 | D21: =OFFSET(报关单!$G$1,ROW(报关单!G13)*3+18,0) -> 0 | E21: =OFFSET(报关单!$H$1,ROW(报关单!H14)*3+18,0) -> 0 | F21: =IFERROR(H21/D21,0) -> 0 | G21: =OFFSET(报关单!$I$1,ROW(报关单!I14)*3+18,0) -> 0 | H21: =OFFSET(报关单!$I$1,ROW(报关单!I13)*3+17,0) -> 0
C22: =OFFSET(报关单!$D$1,ROW(报关单!D14)*3+16,0) -> 0 | D22: =OFFSET(报关单!$G$1,ROW(报关单!G14)*3+18,0) -> 0 | E22: =OFFSET(报关单!$H$1,ROW(报关单!H15)*3+18,0) -> 0 | F22: =IFERROR(H22/D22,0) -> 0 | G22: =OFFSET(报关单!$I$1,ROW(报关单!I15)*3+18,0) -> 0 | H22: =OFFSET(报关单!$I$1,ROW(报关单!I14)*3+17,0) -> 0
A23: =IF(G23="CNY","总计人民币:",IF(G23="USD","总计美元: "," ")) | C23: =H23 -> 24242 | F23: TOTAL: | G23: =G9 -> 美元 | H23: =SUM(H9:H22) -> 24242
A24: 唛头 Marks | F24: 备注：

Sheet 箱单
B2: 装 箱 单 PACKING LIST
F3: 日期 Date： | G3: =报关单!L3 -> 46161
F4: 发票编号 Invoice No: | G4: =发票!G3 -> PK-260512006
A5: 客户 To Messrs: | B5: =发票!C4 -> DURNERGY Inc. | F5: 合同号 Contract No: | G5: =发票!G3 -> PK-260512006
A7: 船名 Shipped by： | C7: 由 深圳 至 | D7: =报关单!M20 -> 美国 | F7: 付款条件 Terms of Payment: | G7: =报关单!Y4 -> 电汇
A9: 箱号 Ctn.No. | B9: 货物名称及规格 Description | C9: 箱数： Pkg： | D9: 数量： Ge.Quantity | F9: 毛重(KG)： G.W.(KG): | G9: 净重(KG)： N.W.(KG):
A10: =发票!A9 -> 0 | B10: =发票!C9 -> 锂电池 | C10: 25 | D10: =发票!D9 -> 28520 | E10: =发票!E9 -> 个 | F10: =24*8.4+8.6 -> 210.2 | G10: =F10-C10*0.5 -> 197.7 | H10: =250/1000*3.7 -> 0.925 | I10: =G10/D10 -> 0.0069319776 | J10: =H10/I10 -> 133.43955 | K10: 251.93
B11: =发票!C17 -> 0 | D11: =发票!D17 -> 0 | E11: =发票!E16 -> 0
B12: =发票!C18 -> 0 | D12: =发票!D18 -> 0 | E12: =发票!E17 -> 0
B13: =发票!C19 -> 0 | D13: =发票!D19 -> 0 | E13: =发票!E18 -> 0
B14: =发票!C20 -> 0 | D14: =发票!D20 -> 0 | E14: =发票!E19 -> 0
B15: =发票!C21 -> 0 | D15: =发票!D21 -> 0 | E15: =发票!E20 -> 0
B16: =发票!C22 -> 0 | D16: =发票!D22 -> 0 | E16: =发票!E21 -> 0
D17: =发票!D23 -> 0 | E17: =发票!E22 -> 0
A18: 合计 Total | C18: =SUM(C10:C17) -> 25 | D18: =SUM(D10:D17) -> 28520 | F18: =SUM(F10:F17) -> 210.2 | G18: =SUM(G10:G17) -> 197.7
A19: 唛头 Marks | B19: =A10 -> 0

Sheet 申报要素
A1: (产品或者包装上有明显的logo，带R，TM标识的商标必须申报为品牌，有显示型号（model，type no.）的必须申报为型号)(申报的牌子型号要在产品或包装上有一模一样显示，海关查货的话会去比对拍照，对不上会升级整车查验和压车改单）
A2: (申报的牌子型号要在产品或包装上有一模一样显示，海关查货的话会去比对拍照，对不上会升级整车查验和压车改单）
A3: 检验检疫附加编号：通过以下网站输入10位HS编号，再根据申报要素细分确定3位检疫附加编号
C4: https://e-service.shciq.gov.cn/shesp/
A5: 申报要素查询网址： | C5: http://www.hscode.net/IntegrateQueries/QueryYS/
A8: 申报要素
A9: 序号 | B9: 品名 | C9: 海关HS编码 | D9: 检疫附加码 | E9: 品牌 | F9: 型号 | G9: 品牌类型 | H9: 出口享惠情况 | I9: 其他申报要素
A10: 1 | G10: 0无品牌 | H10: 0不享惠
A11: 2 | G11: 1境内自主 | H11: 1享惠
A12: 3 | G12: 2境内收购 | H12: 2不确定享惠
A13: 4 | G13: 3境外贴牌
A14: 5 | G14: 4境外其他
A15: 6
A16: 7
A17: 8

Sheet 填制规范
A1: 项目 | B1: 2018年8月实行新的报关单的填制规范，红色为新增的项目
A3: 境内收发货人 | B3: 填报在海关备案的对外签订并执行进出口贸易合同的中国境内法人、其他组织名称及编码。编码填报18位法人和其他组织统一社会信用代码，没有统一社会信用代码的，填报其在海关的备案编码。
A5: 进出境关别 | B5: 根据货物实际进出境的口岸海关，填报海关规定的《关区代码表》中相应口岸海关的名称及代码。
A7: 备案号 | B7: 填报进出口货物收发货人、消费使用单位、生产销售单位在海关办理加工贸易合同备案或征、减、免税审核确认等手续时，海关核发的《加工贸易手册》、海关特殊监管区域和保税监管场所保税账册、《征免税证明》或其他备案审批文件的编号。一份报关单只允许填报一个备案号。
A9: 境外收发货人 | B9: 非互认国家（地区）AEO企业等其他情形，编码免于填报。境外收货人通常指签订并执行出口贸易合同中的买方或合同指定的收货人，境外发货人通常指签订并执行进口贸易合同中的卖方。填报境外收发货人的名称及编码。名称一般填报英文名称，检验检疫要求填报其他外文名称的，在英文名称后填报，以半角括号分隔；对于AEO互认国家（地区）企业的，编码填报AEO编码，填报样式按照海关总署发布的相关公告要求填报（如新加坡AEO企业填报样式为：SG123456789012，韩国AEO企业填报样式为KR1234567，具体见相关公告要求）。
A11: 货物存放地点-进口 | B11: 填报货物进境后存放的场所或地点，包括海关监管作业场所、分拨仓库、定点加工厂、隔离检疫场、企业自有仓库等。
A13: 消费使用单位-进口 | B13: 消费使用单位填报已知的进口货物在境内的最终消费、使用单位的名称，包括：1．自行进口货物的单位。2．委托进出口企业进口货物的单位。
A15: 生产销售单位-出口 | B15: 生产销售单位填报出口货物在境内的生产或销售单位的名称，包括：1．自行出口货物的单位。2．委托进出口企业出口货物的单位。
A17: 许可证号 | B17: 填报进（出）口许可证、两用物项和技术进（出）口许可证、两用物项和技术出口许可证（定向）、纺织品临时出口许可证、出口许可证（加工贸易）、出口许可证（边境小额贸易）的编号。一份报关单只允许填报一个许可证号。
A19: 启运港-进口 | B19: 填报进口货物在运抵我国关境前的第一个境外装运港。
A21: 合同协议号 | B21: 填报进出口货物合同（包括协议或订单）编号。未发生商业性交易的免予填报。
A23: 贸易国(地区) | B23: 发生商业性交易的进口填报购自国（地区），出口填报售予国（地区）。未发生商业性交易的填报货物所有权拥有者所属的国家（地区）。
... A91: 自报自缴 | B91: 进出口企业、单位采用“自主申报、自行缴税”（自报自缴）模式向海关申报时，填报“是”；反之则填报“否”。
